<?xml version="1.0" ?>
<!-- =================================================================================== -->
<!-- |    This document was autogenerated by xacro from dual_arm_iiwa7.urdf.xacro      | -->
<!-- |    EDITING THIS FILE BY HAND IS NOT RECOMMENDED                                 | -->
<!-- =================================================================================== -->
<robot name="dual_iiwa7" xmlns:xacro="http://ros.org/wiki/xacro">
  <!-- Link zur Welt -->
  <link name="world"/>
  <!-- Linker Arm -->
  <joint name="left_arm_base_joint" type="fixed">
    <parent link="world"/>
    <child link="left_lbr1_link_0"/>
    <origin rpy="0.0039    -0.0030   -0.0161" xyz="0.3682   -0.1842    0.7014"/>
  </joint>
  <!-- Beispiel Link mit Prefix -->
  <link name="left_lbr1_link_0">
    <inertial>
      <origin rpy="0 0 0" xyz="-0.012857 0.0 0.069964" />
      <mass value="4.855658" />
      <inertia ixx="0.017839" ixy="0.0" ixz="0.000781" iyy="0.022294" iyz="0.0" izz="0.021334" />
    </inertial>
    <visual>
      <origin rpy="0 0 0" xyz="0 0 0"/>
      <geometry>
        <mesh filename="urdfs/dual_iiwa7/meshes/visual/link_0.stl"/>
      </geometry>
    </visual>
    <collision>
      <origin rpy="0 0 0" xyz="0 0 0"/>
      <geometry>
        <mesh filename="urdfs/dual_iiwa7/meshes/collision/link_0.stl"/>
      </geometry>
    </collision>
  </link>
  <!-- Beispiel Joint mit Prefix -->
  <joint name="left_lbr1_A1" type="revolute">
    <parent link="left_lbr1_link_0"/>
    <child link="left_lbr1_link_1"/>
    <origin rpy="0 0 0" xyz="0 0 0.15"/>
    <axis xyz="0 0 1"/>
    <limit effort="300" lower="-2.96705972839" upper="2.96705972839" velocity="10"/>
    <safety_controller k_position="100" k_velocity="2" soft_lower_limit="-2.93215314335" soft_upper_limit="2.93215314335"/>
    <dynamics damping="0.5"/>
  </joint>
  <link name="left_lbr1_link_1">
    <inertial>
      <origin rpy="0 0.0 0.0" xyz="0.0 1.7109004029720114e-06 -1.4878844771093818e-07"/>
      <inertia ixx="0.0010000000000000057" ixy="-4.2579462382874695e-11" ixz="2.9858415784681634e-13" iyy="0.0017464134769209026" iyz="-5.234148740730177e-06" izz="0.001000036703936742"/>
      <mass value="1.0"/>
    </inertial>
    <visual>
      <origin rpy="0 0 0" xyz="0 0 0.0075"/>
      <geometry>
        <mesh filename="urdfs/dual_iiwa7/meshes/visual/link_1.stl"/>
      </geometry>
    </visual>
    <collision>
      <origin rpy="0 0 0" xyz="0 0 0.0075"/>
      <geometry>
        <mesh filename="urdfs/dual_iiwa7/meshes/collision/link_1.stl"/>
      </geometry>
    </collision>
  </link>
  <joint name="left_lbr1_A2" type="revolute">
    <parent link="left_lbr1_link_1"/>
    <child link="left_lbr1_link_2"/>
    <origin rpy="1.57079632679   0 3.14159265359" xyz="0 0 0.19"/>
    <axis xyz="0 0 1"/>
    <limit effort="300" lower="-2.09439510239" upper="2.09439510239" velocity="10"/>
    <safety_controller k_position="100" k_velocity="2" soft_lower_limit="-2.05948851735" soft_upper_limit="2.05948851735"/>
    <dynamics damping="0.5"/>
  </joint>
  <link name="left_lbr1_link_2">
    <inertial>
      <origin rpy="0 0.0 0.0" xyz="0.0 -0.25 -0.020970471292012287"/>
      <inertia ixx="0.10426933444917176" ixy="-0.05668572121468018" ixz="0.01946041056168691" iyy="0.03239098553421302" iyz="-0.016501525407836892" izz="0.12757475410195904"/>
      <mass value="3.003961342802758"/>
    </inertial>
    <visual>
      <origin rpy="0 0 0" xyz="0 0 0"/>
      <geometry>
        <mesh filename="urdfs/dual_iiwa7/meshes/visual/link_2.stl"/>
      </geometry>
    </visual>
    <collision>
      <origin rpy="0 0 0" xyz="0 0 0"/>
      <geometry>
        <mesh filename="urdfs/dual_iiwa7/meshes/collision/link_2.stl"/>
      </geometry>
    </collision>
  </link>
  <joint name="left_lbr1_A3" type="revolute">
    <parent link="left_lbr1_link_2"/>
    <child link="left_lbr1_link_3"/>
    <origin rpy="1.57079632679 0 3.14159265359" xyz="0 0.21 0"/>
    <axis xyz="0 0 1"/>
    <limit effort="300" lower="-2.96705972839" upper="2.96705972839" velocity="10"/>
    <safety_controller k_position="100" k_velocity="2" soft_lower_limit="-2.93215314335" soft_upper_limit="2.93215314335"/>
    <dynamics damping="0.5"/>
  </joint>
  <link name="left_lbr1_link_3">
    <inertial>
      <origin rpy="0 0.0 0.0" xyz="0.0 0.011177748418303282 -0.11214653732414659"/>
      <inertia ixx="0.08828514948801965" ixy="-0.033330374495470216" ixz="0.014152731342729704" iyy="0.01372740976585913" iyz="-0.005404308047289371" izz="0.003294775292639863"/>
      <mass value="3.050226496289256"/>
    </inertial>
    <visual>
      <origin rpy="0 0 0" xyz="0 0 -0.026"/>
      <geometry>
        <mesh filename="urdfs/dual_iiwa7/meshes/visual/link_3.stl"/>
      </geometry>
    </visual>
    <collision>
      <origin rpy="0 0 0" xyz="0 0 -0.026"/>
      <geometry>
        <mesh filename="urdfs/dual_iiwa7/meshes/collision/link_3.stl"/>
      </geometry>
    </collision>
  </link>
  <joint name="left_lbr1_A4" type="revolute">
    <parent link="left_lbr1_link_3"/>
    <child link="left_lbr1_link_4"/>
    <origin rpy="1.57079632679 0 0" xyz="0 0 0.19"/>
    <axis xyz="0 0 1"/>
    <limit effort="300" lower="-2.09439510239" upper="2.09439510239" velocity="10"/>
    <safety_controller k_position="100" k_velocity="2" soft_lower_limit="-2.05948851735" soft_upper_limit="2.05948851735"/>
    <dynamics damping="0.5"/>
  </joint>
  <link name="left_lbr1_link_4">
    <inertial>
      <origin rpy="0 0.0 0.0" xyz="0.0 0.13197287187092396 0.01601064120048604"/>
      <inertia ixx="0.015212924352077327" ixy="0.005295085257727219" ixz="-0.033958140583600804" iyy="0.0029727064741959463" iyz="-0.012651249322787857" izz="0.08213427492682435"/>
      <mass value="2.7724994264662612"/>
    </inertial>
    <visual>
      <origin rpy="0 0 0" xyz="0 0 0"/>
      <geometry>
        <mesh filename="urdfs/dual_iiwa7/meshes/visual/link_4.stl"/>
      </geometry>
    </visual>
    <collision>
      <origin rpy="0 0 0" xyz="0 0 0"/>
      <geometry>
        <mesh filename="urdfs/dual_iiwa7/meshes/collision/link_4.stl"/>
      </geometry>
    </collision>
  </link>
  <joint name="left_lbr1_A5" type="revolute">
    <parent link="left_lbr1_link_4"/>
    <child link="left_lbr1_link_5"/>
    <origin rpy="-1.57079632679 3.14159265359 0" xyz="0 0.21 0"/>
    <axis xyz="0 0 1"/>
    <limit effort="300" lower="-2.96705972839" upper="2.96705972839" velocity="10"/>
    <safety_controller k_position="100" k_velocity="2" soft_lower_limit="-2.93215314335" soft_upper_limit="2.93215314335"/>
    <dynamics damping="0.5"/>
  </joint>
  <link name="left_lbr1_link_5">
    <inertial>
      <origin rpy="0 0.0 0.0" xyz="0.0 -0.0018318708076270997 -0.25"/>
      <inertia ixx="0.015621699445557373" ixy="0.021001779831434843" ixz="-0.003357861321471057" iyy="0.03116576545909502" iyz="-0.0048230415650796984" izz="0.0017711301067440013"/>
      <mass value="2.676573572819668"/>
    </inertial>
    <visual>
      <origin rpy="0 0 0" xyz="0 0 -0.026"/>
      <geometry>
        <mesh filename="urdfs/dual_iiwa7/meshes/visual/link_5.stl"/>
      </geometry>
    </visual>
    <collision>
      <origin rpy="0 0 0" xyz="0 0 -0.026"/>
      <geometry>
        <mesh filename="urdfs/dual_iiwa7/meshes/collision/link_5.stl"/>
      </geometry>
    </collision>
  </link>
  <joint name="left_lbr1_A6" type="revolute">
    <parent link="left_lbr1_link_5"/>
    <child link="left_lbr1_link_6"/>
    <origin rpy="1.57079632679 0 0" xyz="0 0.06070 0.19"/>
    <axis xyz="0 0 1"/>
    <limit effort="300" lower="-2.09439510239" upper="2.09439510239" velocity="10"/>
    <safety_controller k_position="100" k_velocity="2" soft_lower_limit="-2.05948851735" soft_upper_limit="2.05948851735"/>
    <dynamics damping="0.5"/>
  </joint>
  <link name="left_lbr1_link_6">
    <inertial>
      <origin rpy="0 0.0 0.0" xyz="0.0 -0.02285889421663758 -0.03501332012234617"/>
      <inertia ixx="0.016822528844185836" ixy="0.00440162568108521" ixz="-0.004485192046791866" iyy="0.0022244761142279825" iyz="-0.001247723211135917" izz="0.0022714116621122323"/>
      <mass value="1.9709456359242412"/>
    </inertial>
    <visual>
      <origin rpy="0 0 0" xyz="0 0 0"/>
      <geometry>
        <mesh filename="urdfs/dual_iiwa7/meshes/visual/link_6.stl"/>
      </geometry>
    </visual>
    <collision>
      <origin rpy="0 0 0" xyz="0 0 0"/>
      <geometry>
        <mesh filename="urdfs/dual_iiwa7/meshes/collision/link_6.stl"/>
      </geometry>
    </collision>
  </link>
  <joint name="left_lbr1_A7" type="revolute">
    <parent link="left_lbr1_link_6"/>
    <child link="left_lbr1_link_7"/>
    <origin rpy="-1.57079632679 3.14159265359 0" xyz="0 0.081 0.06070"/>
    <axis xyz="0 0 1"/>
    <limit effort="300" lower="-3.05432619099" upper="3.05432619099" velocity="10"/>
    <safety_controller k_position="100" k_velocity="2" soft_lower_limit="-3.01941960595" soft_upper_limit="3.01941960595"/>
    <dynamics damping="0.5"/>
  </joint>
  <link name="left_lbr1_link_7">
    <inertial>
      <origin rpy="0 0.0 0.0" xyz="0.0 -0.0016332365708782504 -0.09761086920058419"/>
      <inertia ixx="0.0010007264948202847" ixy="3.9720199777362234e-05" ixz="-2.8581304617466147e-06" iyy="0.003171652469229627" iyz="-0.0001562647244833329" izz="0.0010112442780158624"/>
      <mass value="1.7379073850248012"/>
    </inertial>
    <visual>
      <origin rpy="0 0 0" xyz="0 0 -0.0005"/>
      <geometry>
        <mesh filename="urdfs/dual_iiwa7/meshes/visual/link_7.stl"/>
      </geometry>
    </visual>
    <collision>
      <origin rpy="0 0 0" xyz="0 0 -0.0005"/>
      <geometry>
        <mesh filename="urdfs/dual_iiwa7/meshes/collision/link_7.stl"/>
      </geometry>
    </collision>
  </link>
  <!-- end effector without gripper -->
  <joint name="left_lbr1_joint_ee" type="fixed">
    <parent link="left_lbr1_link_7"/>
    <child link="left_lbr1_link_ee"/>
    <origin rpy="0.0 0.0 0.0" xyz="0.0 0.0 0.045"/>
  </joint>
  <link name="left_lbr1_link_ee">
  </link>
  
  <!-- Rechter Arm -->
  <joint name="right_arm_base_joint" type="fixed">
    <parent link="world"/>
    <child link="right_lbr1_link_0"/>
    <origin rpy="-0.0012    0.0001   -0.0158" xyz="0.3743    0.1816    0.7048"/>
  </joint>
  <!-- Beispiel Link mit Prefix -->
  <link name="right_lbr1_link_0">
    <inertial>
      <origin rpy="0 0 0" xyz="-0.012857 0.0 0.069964"/>
      <mass value="4.855658"/>
      <inertia ixx="0.017839" ixy="0.0" ixz="0.000781" iyy="0.022294" iyz="0.0" izz="0.021334"/>
    </inertial>
    <visual>
      <origin rpy="0 0 0" xyz="0 0 0"/>
      <geometry>
        <mesh filename="urdfs/dual_iiwa7/meshes/visual/link_0.stl"/>
      </geometry>
    </visual>
    <collision>
      <origin rpy="0 0 0" xyz="0 0 0"/>
      <geometry>
        <mesh filename="urdfs/dual_iiwa7/meshes/collision/link_0.stl"/>
      </geometry>
    </collision>
  </link>
  <!-- Beispiel Joint mit Prefix -->
  <joint name="right_lbr1_A1" type="revolute">
    <parent link="right_lbr1_link_0"/>
    <child link="right_lbr1_link_1"/>
    <origin rpy="0 0 0" xyz="0 0 0.15"/>
    <axis xyz="0 0 1"/>
    <limit effort="300" lower="-2.96705972839" upper="2.96705972839" velocity="10"/>
    <safety_controller k_position="100" k_velocity="2" soft_lower_limit="-2.93215314335" soft_upper_limit="2.93215314335"/>
    <dynamics damping="0.5"/>
  </joint>
  <link name="right_lbr1_link_1">
    <inertial>
      <origin rpy="0 0.0 0.0" xyz="0.0 1.7109004029720114e-06 -1.4878844771093818e-07"/>
      <inertia ixx="0.0010000000000000057" ixy="-4.2579462382874695e-11" ixz="2.9858415784681634e-13" iyy="0.0017464134769209026" iyz="-5.234148740730177e-06" izz="0.001000036703936742"/>
      <mass value="1.0"/>
    </inertial>
    <visual>
      <origin rpy="0 0 0" xyz="0 0 0.0075"/>
      <geometry>
        <mesh filename="urdfs/dual_iiwa7/meshes/visual/link_1.stl"/>
      </geometry>
    </visual>
    <collision>
      <origin rpy="0 0 0" xyz="0 0 0.0075"/>
      <geometry>
        <mesh filename="urdfs/dual_iiwa7/meshes/collision/link_1.stl"/>
      </geometry>
    </collision>
  </link>
  <joint name="right_lbr1_A2" type="revolute">
    <parent link="right_lbr1_link_1"/>
    <child link="right_lbr1_link_2"/>
    <origin rpy="1.57079632679   0 3.14159265359" xyz="0 0 0.19"/>
    <axis xyz="0 0 1"/>
    <limit effort="300" lower="-2.09439510239" upper="2.09439510239" velocity="10"/>
    <safety_controller k_position="100" k_velocity="2" soft_lower_limit="-2.05948851735" soft_upper_limit="2.05948851735"/>
    <dynamics damping="0.5"/>
  </joint>
  <link name="right_lbr1_link_2">
    <inertial>
      <!-- stays 0 -->
      <origin rpy="0 0.0 0.0" xyz="0.0 -0.25 -0.020970471292012287"/>
      <inertia ixx="0.10426933444917176" ixy="-0.05668572121468018" ixz="0.01946041056168691" iyy="0.03239098553421302" iyz="-0.016501525407836892" izz="0.12757475410195904"/>
      <mass value="3.003961342802758"/>
    </inertial>
    <visual>
      <origin rpy="0 0 0" xyz="0 0 0"/>
      <geometry>
        <mesh filename="urdfs/dual_iiwa7/meshes/visual/link_2.stl"/>
      </geometry>
    </visual>
    <collision>
      <origin rpy="0 0 0" xyz="0 0 0"/>
      <geometry>
        <mesh filename="urdfs/dual_iiwa7/meshes/collision/link_2.stl"/>
      </geometry>
    </collision>
  </link>
  <joint name="right_lbr1_A3" type="revolute">
    <parent link="right_lbr1_link_2"/>
    <child link="right_lbr1_link_3"/>
    <origin rpy="1.57079632679 0 3.14159265359" xyz="0 0.21 0"/>
    <axis xyz="0 0 1"/>
    <limit effort="300" lower="-2.96705972839" upper="2.96705972839" velocity="10"/>
    <safety_controller k_position="100" k_velocity="2" soft_lower_limit="-2.93215314335" soft_upper_limit="2.93215314335"/>
    <dynamics damping="0.5"/>
  </joint>
  <link name="right_lbr1_link_3">
    <inertial>
      <origin rpy="0 0.0 0.0" xyz="0.0 0.011177748418303282 -0.11214653732414659"/>
      <inertia ixx="0.08828514948801965" ixy="-0.033330374495470216" ixz="0.014152731342729704" iyy="0.01372740976585913" iyz="-0.005404308047289371" izz="0.003294775292639863"/>
      <mass value="3.050226496289256"/>
    </inertial>
    <visual>
      <origin rpy="0 0 0" xyz="0 0 -0.026"/>
      <geometry>
        <mesh filename="urdfs/dual_iiwa7/meshes/visual/link_3.stl"/>
      </geometry>
    </visual>
    <collision>
      <origin rpy="0 0 0" xyz="0 0 -0.026"/>
      <geometry>
        <mesh filename="urdfs/dual_iiwa7/meshes/collision/link_3.stl"/>
      </geometry>
    </collision>
  </link>
  <joint name="right_lbr1_A4" type="revolute">
    <parent link="right_lbr1_link_3"/>
    <child link="right_lbr1_link_4"/>
    <origin rpy="1.57079632679 0 0" xyz="0 0 0.19"/>
    <axis xyz="0 0 1"/>
    <limit effort="300" lower="-2.09439510239" upper="2.09439510239" velocity="10"/>
    <safety_controller k_position="100" k_velocity="2" soft_lower_limit="-2.05948851735" soft_upper_limit="2.05948851735"/>
    <dynamics damping="0.5"/>
  </joint>
  <link name="right_lbr1_link_4">
    <inertial>
      <origin rpy="0 0.0 0.0" xyz="0.0 0.13197287187092396 0.01601064120048604"/>
      <inertia ixx="0.015212924352077327" ixy="0.005295085257727219" ixz="-0.033958140583600804" iyy="0.0029727064741959463" iyz="-0.012651249322787857" izz="0.08213427492682435"/>
      <mass value="2.7724994264662612"/>
    </inertial>
    <visual>
      <origin rpy="0 0 0" xyz="0 0 0"/>
      <geometry>
        <mesh filename="urdfs/dual_iiwa7/meshes/visual/link_4.stl"/>
      </geometry>
    </visual>
    <collision>
      <origin rpy="0 0 0" xyz="0 0 0"/>
      <geometry>
        <mesh filename="urdfs/dual_iiwa7/meshes/collision/link_4.stl"/>
      </geometry>
    </collision>
  </link>
  <joint name="right_lbr1_A5" type="revolute">
    <parent link="right_lbr1_link_4"/>
    <child link="right_lbr1_link_5"/>
    <origin rpy="-1.57079632679 3.14159265359 0" xyz="0 0.21 0"/>
    <axis xyz="0 0 1"/>
    <limit effort="300" lower="-2.96705972839" upper="2.96705972839" velocity="10"/>
    <safety_controller k_position="100" k_velocity="2" soft_lower_limit="-2.93215314335" soft_upper_limit="2.93215314335"/>
    <dynamics damping="0.5"/>
  </joint>
  <link name="right_lbr1_link_5">
    <inertial>
      <origin rpy="0 0.0 0.0" xyz="0.0 -0.0018318708076270997 -0.25"/>
      <inertia ixx="0.015621699445557373" ixy="0.021001779831434843" ixz="-0.003357861321471057" iyy="0.03116576545909502" iyz="-0.0048230415650796984" izz="0.0017711301067440013"/>
      <mass value="2.676573572819668"/>
    </inertial>
    <visual>
      <origin rpy="0 0 0" xyz="0 0 -0.026"/>
      <geometry>
        <mesh filename="urdfs/dual_iiwa7/meshes/visual/link_5.stl"/>
      </geometry>
    </visual>
    <collision>
      <origin rpy="0 0 0" xyz="0 0 -0.026"/>
      <geometry>
        <mesh filename="urdfs/dual_iiwa7/meshes/collision/link_5.stl"/>
      </geometry>
    </collision>
  </link>
  <joint name="right_lbr1_A6" type="revolute">
    <parent link="right_lbr1_link_5"/>
    <child link="right_lbr1_link_6"/>
    <origin rpy="1.57079632679 0 0" xyz="0 0.06070 0.19"/>
    <axis xyz="0 0 1"/>
    <limit effort="300" lower="-2.09439510239" upper="2.09439510239" velocity="10"/>
    <safety_controller k_position="100" k_velocity="2" soft_lower_limit="-2.05948851735" soft_upper_limit="2.05948851735"/>
    <dynamics damping="0.5"/>
  </joint>
  <link name="right_lbr1_link_6">
    <inertial>
      <origin rpy="0 0.0 0.0" xyz="0.0 -0.02285889421663758 -0.03501332012234617"/>
      <inertia ixx="0.016822528844185836" ixy="0.00440162568108521" ixz="-0.004485192046791866" iyy="0.0022244761142279825" iyz="-0.001247723211135917" izz="0.0022714116621122323"/>
      <mass value="1.9709456359242412"/>
    </inertial>
    <visual>
      <origin rpy="0 0 0" xyz="0 0 0"/>
      <geometry>
        <mesh filename="urdfs/dual_iiwa7/meshes/visual/link_6.stl"/>
      </geometry>
    </visual>
    <collision>
      <origin rpy="0 0 0" xyz="0 0 0"/>
      <geometry>
        <mesh filename="urdfs/dual_iiwa7/meshes/collision/link_6.stl"/>
      </geometry>
    </collision>
  </link>
  <joint name="right_lbr1_A7" type="revolute">
    <parent link="right_lbr1_link_6"/>
    <child link="right_lbr1_link_7"/>
    <origin rpy="-1.57079632679 3.14159265359 0" xyz="0 0.081 0.06070"/>
    <axis xyz="0 0 1"/>
    <limit effort="300" lower="-3.05432619099" upper="3.05432619099" velocity="10"/>
    <safety_controller k_position="100" k_velocity="2" soft_lower_limit="-3.01941960595" soft_upper_limit="3.01941960595"/>
    <dynamics damping="0.5"/>
  </joint>
  <link name="right_lbr1_link_7">
    <inertial>
      <origin rpy="0 0.0 0.0" xyz="0.0 -0.0016332365708782504 -0.09761086920058419"/>
      <inertia ixx="0.0010007264948202847" ixy="3.9720199777362234e-05" ixz="-2.8581304617466147e-06" iyy="0.003171652469229627" iyz="-0.0001562647244833329" izz="0.0010112442780158624"/>
      <mass value="1.7379073850248012"/>
    </inertial>
    <visual>
      <origin rpy="0 0 0" xyz="0 0 -0.0005"/>
      <geometry>
        <mesh filename="urdfs/dual_iiwa7/meshes/visual/link_7.stl"/>
      </geometry>
    </visual>
    <collision>
      <origin rpy="0 0 0" xyz="0 0 -0.0005"/>
      <geometry>
        <mesh filename="urdfs/dual_iiwa7/meshes/collision/link_7.stl"/>
      </geometry>
    </collision>
  </link>
  <!-- end effector without gripper -->
  <joint name="right_lbr1_joint_ee" type="fixed">
    <parent link="right_lbr1_link_7"/>
    <child link="right_lbr1_link_ee"/>
    <origin rpy="0.0 0.0 0.0" xyz="0.0 0.0 0.045"/>
  </joint>
  <link name="right_lbr1_link_ee"/>
</robot>

