<?xml version="1.0" encoding="utf-8"?>
<!-- =================================================================================== -->
<!-- |    This document was autogenerated by xacro from iiwa7.urdf.xacro               | -->
<!-- |    EDITING THIS FILE BY HAND IS NOT RECOMMENDED                                 | -->
<!-- =================================================================================== -->
<robot name="iiwa7_0">
    <!-- Fix to world just for testing -->
    <link name="world"/>
    <!--joint between {parent} and link_0-->
    <joint name="lbr1_world_iiwa_joint" type="fixed">
        <origin xyz="0.3682   -0.1842    0.7014" rpy="0.0039    -0.0030   -0.0161"/>
        <parent link="world"/>
        <child link="lbr1_link_0"/>
    </joint>
    <link name="lbr1_link_0">
        <visual>
            <origin rpy="0 0 0" xyz="0 0 0"/>
            <geometry>
                <mesh filename="iiwa7/visual/base.dae"/>
            </geometry>
            
        </visual>
        <collision>
            <origin rpy="0 0 0" xyz="0 0 0"/>
            <geometry>
                <mesh filename="iiwa7/collision/link_0.stl"/>
            </geometry>
        </collision>
    </link>
    <!-- joint between link_0 and link_1 -->
    <joint name="lbr1_A1" type="revolute">
        <parent link="lbr1_link_0"/>
        <child link="lbr1_link_1"/>
        <origin rpy="0 0 0" xyz="0 0 0.15"/>
        <axis xyz="0 0 1"/>
        <limit effort="300" lower="-2.96705972839" upper="2.96705972839" velocity="10"/>
        <safety_controller k_position="100" k_velocity="2" soft_lower_limit="-2.93215314335" soft_upper_limit="2.93215314335"/>
        <dynamics damping="0.5"/>
    </joint>
    <link name="lbr1_link_1">
        <visual>
            <origin rpy="0 0 0" xyz="0 0 0.0075"/>
            <geometry>
                <mesh filename="iiwa7/visual/link1.dae"/>
            </geometry>
            
        </visual>
        <collision>
            <origin rpy="0 0 0" xyz="0 0 0.0075"/>
            <geometry>
                <mesh filename="iiwa7/collision/link_1.stl"/>
            </geometry>
            
        </collision>
    </link>
    <joint name="lbr1_A2" type="revolute">
        <parent link="lbr1_link_1"/>
        <child link="lbr1_link_2"/>
        <origin rpy="1.57079632679   0 3.14159265359" xyz="0 0 0.19"/>
        <axis xyz="0 0 1"/>
        <limit effort="300" lower="-2.09439510239" upper="2.09439510239" velocity="10"/>
        <safety_controller k_position="100" k_velocity="2" soft_lower_limit="-2.05948851735" soft_upper_limit="2.05948851735"/>
        <dynamics damping="0.5"/>
    </joint>
    <link name="lbr1_link_2">
        <visual>
            <origin rpy="0 0 0" xyz="0 0 0"/>
            <geometry>
                <mesh filename="iiwa7/visual/link2.dae"/>
            </geometry>
            
        </visual>
        <collision>
            <origin rpy="0 0 0" xyz="0 0 0"/>
            <geometry>
                <mesh filename="iiwa7/collision/link_2.stl"/>
            </geometry>
            
        </collision>
    </link>
    <joint name="lbr1_A3" type="revolute">
        <parent link="lbr1_link_2"/>
        <child link="lbr1_link_3"/>
        <origin rpy="1.57079632679 0 3.14159265359" xyz="0 0.21 0"/>
        <axis xyz="0 0 1"/>
        <limit effort="300" lower="-2.96705972839" upper="2.96705972839" velocity="10"/>
        <safety_controller k_position="100" k_velocity="2" soft_lower_limit="-2.93215314335" soft_upper_limit="2.93215314335"/>
        <dynamics damping="0.5"/>
    </joint>
    <link name="lbr1_link_3">
        <visual>
            <origin rpy="0 0 0" xyz="0 0 -0.026"/>
            <geometry>
                <mesh filename="iiwa7/visual/link3.dae"/>
            </geometry>
            
        </visual>
        <collision>
            <origin rpy="0 0 0" xyz="0 0 -0.026"/>
            <geometry>
                <mesh filename="iiwa7/collision/link_3.stl"/>
            </geometry>
            
        </collision>
    </link>
    <joint name="lbr1_A4" type="revolute">
        <parent link="lbr1_link_3"/>
        <child link="lbr1_link_4"/>
        <origin rpy="1.57079632679 0 0" xyz="0 0 0.19"/>
        <axis xyz="0 0 1"/>
        <limit effort="300" lower="-2.09439510239" upper="2.09439510239" velocity="10"/>
        <safety_controller k_position="100" k_velocity="2" soft_lower_limit="-2.05948851735" soft_upper_limit="2.05948851735"/>
        <dynamics damping="0.5"/>
    </joint>
    <link name="lbr1_link_4">
        <visual>
            <origin rpy="0 0 0" xyz="0 0 0"/>
            <geometry>
                <mesh filename="iiwa7/visual/link4.dae"/>
            </geometry>
            
        </visual>
        <collision>
            <origin rpy="0 0 0" xyz="0 0 0"/>
            <geometry>
                <mesh filename="iiwa7/collision/link_4.stl"/>
            </geometry>
            
        </collision>
    </link>
    <joint name="lbr1_A5" type="revolute">
        <parent link="lbr1_link_4"/>
        <child link="lbr1_link_5"/>
        <origin rpy="-1.57079632679 3.14159265359 0" xyz="0 0.21 0"/>
        <axis xyz="0 0 1"/>
        <limit effort="300" lower="-2.96705972839" upper="2.96705972839" velocity="10"/>
        <safety_controller k_position="100" k_velocity="2" soft_lower_limit="-2.93215314335" soft_upper_limit="2.93215314335"/>
        <dynamics damping="0.5"/>
    </joint>
    <link name="lbr1_link_5">
        <visual>
            <origin rpy="0 0 0" xyz="0 0 -0.026"/>
            <geometry>
                <mesh filename="iiwa7/visual/link5.dae"/>
            </geometry>
            
        </visual>
        <collision>
            <origin rpy="0 0 0" xyz="0 0 -0.026"/>
            <geometry>
                <mesh filename="iiwa7/collision/link_5.stl"/>
            </geometry>
            
        </collision>
    </link>
    <joint name="lbr1_A6" type="revolute">
        <parent link="lbr1_link_5"/>
        <child link="lbr1_link_6"/>
        <origin rpy="1.57079632679 0 0" xyz="0 0.06070 0.19"/>
        <axis xyz="0 0 1"/>
        <limit effort="300" lower="-2.09439510239" upper="2.09439510239" velocity="10"/>
        <safety_controller k_position="100" k_velocity="2" soft_lower_limit="-2.05948851735" soft_upper_limit="2.05948851735"/>
        <dynamics damping="0.5"/>
    </joint>
    <link name="lbr1_link_6">
        <visual>
            <origin rpy="0 0 0" xyz="0 0 0"/>
            <geometry>
                <mesh filename="iiwa7/visual/link6.dae"/>
            </geometry>
            
        </visual>
        <collision>
            <origin rpy="0 0 0" xyz="0 0 0"/>
            <geometry>
                <mesh filename="iiwa7/collision/link_6.stl"/>
            </geometry>
            
        </collision>
    </link>
    <joint name="lbr1_A7" type="revolute">
        <parent link="lbr1_link_6"/>
        <child link="lbr1_link_7"/>
        <origin rpy="-1.57079632679 3.14159265359 0" xyz="0 0.081 0.06070"/>
        <axis xyz="0 0 1"/>
        <limit effort="300" lower="-3.05432619099" upper="3.05432619099" velocity="10"/>
        <safety_controller k_position="100" k_velocity="2" soft_lower_limit="-3.01941960595" soft_upper_limit="3.01941960595"/>
        <dynamics damping="0.5"/>
    </joint>
    <link name="lbr1_link_7">
        <inertial>
            <origin rpy="0 0 0" xyz="0 0 0.02"/>
            <mass value="3.129"/>
            <inertia ixx="0.01464" ixy="0.0005912" ixz="0" iyy="0.01465" iyz="0" izz="0.002872"/>
        </inertial>
        <visual>
            <origin rpy="0 0 0" xyz="0 0 -0.0005"/>
            <geometry>
                <mesh filename="iiwa7/visual/link7.dae"/>
            </geometry>
            
        </visual>
        <collision>
            <origin rpy="0 0 0" xyz="0 0 -0.0005"/>
            <geometry>
                <mesh filename="iiwa7/collision/link_7.stl"/>
            </geometry>
            
        </collision>
    </link>
        <!-- end effector without gripper -->
    <joint name="lbr1_joint_ee" type="fixed">
        <parent link="lbr1_link_7"/>
        <child link="lbr1_link_ee"/>
        <origin rpy="0.0 0.0 0.0" xyz="0.0 0.0 0.045"/>
    </joint>
    <link name="lbr1_link_ee"/>
    <joint name="lbr1_joint_gripper" type="fixed">
        <parent link="lbr1_link_ee"/>
        <child link="lbr1_link_gripper"/>
        <origin rpy="0 0 0" xyz="0 0 0"/>
    </joint>
    <!-- weight ,CoG and TCP can be obtained from onrobot web application CoG/TCP -->
    <link name="lbr1_link_gripper">
        <inertial>
            <origin rpy="0 0 0" xyz="0 0 0.0625"/>
            <mass value="1.2"/>
            <inertia ixx="0.00219" ixy="0" ixz="0" iyy="0.00219" iyz="0" izz="0.0015"/>
        </inertial>
        <visual>
            <origin rpy="0 0 0" xyz="0 0 0"/>
            <geometry>
                <mesh filename="meshes/onrobot_2fg7/2fg7_module.dae"/>
            </geometry>
        </visual>
        <collision>
            <origin rpy="0 0 0" xyz="0 0 0.06"/>
            <geometry>
                <cylinder length="0.12" radius="0.055"/>
            </geometry>
        </collision>
    </link>
    <joint name="lbr1_gripper_ee" type="fixed">
        <parent link="lbr1_link_ee"/>
        <child link="lbr1_gripper_link_ee"/>
        <origin rpy="0 0 0" xyz="0 0 0.14"/>
    </joint>
    <link name="lbr1_gripper_link_ee"/>
    <joint name="lbr1_right_finger_joint" type="fixed">
        <origin rpy="0 0 0" xyz="0 0.006 0"/>
        <parent link="lbr1_link_gripper"/>
        <child link="lbr1_right_finger_link"/>
    </joint>
    <joint name="lbr1_left_finger_joint" type="fixed">
        <origin rpy="0 0 0" xyz="0 -0.006 0"/>
        <parent link="lbr1_link_gripper"/>
        <child link="lbr1_left_finger_link"/>
    </joint>

    <link name="lbr1_right_finger_link">
        <visual>
            <origin rpy="0 0 0" xyz="0 0 0"/>
            <geometry>
                <mesh filename="meshes/onrobot_2fg7/2fg7_gripper_right.dae"/>
            </geometry>
        </visual>
        <collision name="lbr1_right_finger_collision">
            <origin rpy="0 0 0" xyz="0 0 0"/>
            <geometry>
                <mesh filename="meshes/onrobot_2fg7/2fg7_gripper_right.dae"/>
            </geometry>
        </collision>
    </link>
    <link name="lbr1_left_finger_link">
        <visual>
            <origin rpy="0 0 0" xyz="0 0 0"/>
            <geometry>
                <mesh filename="meshes/onrobot_2fg7/2fg7_gripper_left.dae"/>
            </geometry>
        </visual>
        <collision name="lbr1_left_finger_collision">
            <origin rpy="0 0 0" xyz="0 0 0"/>
            <geometry>
                <mesh filename="meshes/onrobot_2fg7/2fg7_gripper_left.dae"/>
            </geometry>
        </collision>
    </link>
</robot>
